[2025-05-07T06:12:36.117+0000] {taskinstance.py:1159} INFO - Dependencies all met for dep_context=non-requeueable deps ti=<TaskInstance: lgbtq_model_pipeline.get_metrics manual__2025-05-07T05:45:40.059879+00:00 [queued]>
[2025-05-07T06:12:36.123+0000] {taskinstance.py:1159} INFO - Dependencies all met for dep_context=requeueable deps ti=<TaskInstance: lgbtq_model_pipeline.get_metrics manual__2025-05-07T05:45:40.059879+00:00 [queued]>
[2025-05-07T06:12:36.125+0000] {taskinstance.py:1361} INFO - Starting attempt 1 of 1
[2025-05-07T06:12:36.135+0000] {taskinstance.py:1382} INFO - Executing <Task(PythonOperator): get_metrics> on 2025-05-07 05:45:40.059879+00:00
[2025-05-07T06:12:36.143+0000] {standard_task_runner.py:57} INFO - Started process 6311 to run task
[2025-05-07T06:12:36.147+0000] {standard_task_runner.py:84} INFO - Running: ['***', 'tasks', 'run', 'lgbtq_model_pipeline', 'get_metrics', 'manual__2025-05-07T05:45:40.059879+00:00', '--job-id', '51', '--raw', '--subdir', 'DAGS_FOLDER/lgbtq_model_pipeline.py', '--cfg-path', '/tmp/tmpd_0r4dtg']
[2025-05-07T06:12:36.150+0000] {standard_task_runner.py:85} INFO - Job 51: Subtask get_metrics
[2025-05-07T06:12:36.176+0000] {task_command.py:416} INFO - Running <TaskInstance: lgbtq_model_pipeline.get_metrics manual__2025-05-07T05:45:40.059879+00:00 [running]> on host 6fdcfcafebfc
[2025-05-07T06:12:36.214+0000] {taskinstance.py:1662} INFO - Exporting env vars: AIRFLOW_CTX_DAG_OWNER='***' AIRFLOW_CTX_DAG_ID='lgbtq_model_pipeline' AIRFLOW_CTX_TASK_ID='get_metrics' AIRFLOW_CTX_EXECUTION_DATE='2025-05-07T05:45:40.059879+00:00' AIRFLOW_CTX_TRY_NUMBER='1' AIRFLOW_CTX_DAG_RUN_ID='manual__2025-05-07T05:45:40.059879+00:00'
[2025-05-07T06:12:36.215+0000] {logging_mixin.py:154} INFO - üìè Evaluating latest models...
[2025-05-07T06:12:36.216+0000] {taskinstance.py:1937} ERROR - Task failed with exception
Traceback (most recent call last):
  File "/home/airflow/.local/lib/python3.8/site-packages/airflow/operators/python.py", line 192, in execute
    return_value = self.execute_callable()
  File "/home/airflow/.local/lib/python3.8/site-packages/airflow/operators/python.py", line 209, in execute_callable
    return self.python_callable(*self.op_args, **self.op_kwargs)
  File "/opt/airflow/dags/tasks/get_metrics.py", line 70, in run
    new_acc = evaluate_model(os.path.join(MODEL_DIR, new_model))
  File "/opt/airflow/dags/tasks/get_metrics.py", line 49, in evaluate_model
    model = TripletNet(model_name=MODEL_NAME).to(device)
TypeError: __init__() got an unexpected keyword argument 'model_name'
[2025-05-07T06:12:36.222+0000] {taskinstance.py:1400} INFO - Marking task as FAILED. dag_id=lgbtq_model_pipeline, task_id=get_metrics, execution_date=20250507T054540, start_date=20250507T061236, end_date=20250507T061236
[2025-05-07T06:12:36.228+0000] {standard_task_runner.py:104} ERROR - Failed to execute job 51 for task get_metrics (__init__() got an unexpected keyword argument 'model_name'; 6311)
[2025-05-07T06:12:36.248+0000] {local_task_job_runner.py:228} INFO - Task exited with return code 1
[2025-05-07T06:12:36.264+0000] {taskinstance.py:2778} INFO - 0 downstream tasks scheduled from follow-on schedule check
