[2025-05-07T01:22:55.868+0000] {taskinstance.py:1159} INFO - Dependencies all met for dep_context=non-requeueable deps ti=<TaskInstance: lgbtq_model_pipeline.retrain scheduled__2025-05-06T00:00:00+00:00 [queued]>
[2025-05-07T01:22:55.873+0000] {taskinstance.py:1159} INFO - Dependencies all met for dep_context=requeueable deps ti=<TaskInstance: lgbtq_model_pipeline.retrain scheduled__2025-05-06T00:00:00+00:00 [queued]>
[2025-05-07T01:22:55.873+0000] {taskinstance.py:1361} INFO - Starting attempt 1 of 1
[2025-05-07T01:22:55.879+0000] {taskinstance.py:1382} INFO - Executing <Task(PythonOperator): retrain> on 2025-05-06 00:00:00+00:00
[2025-05-07T01:22:55.884+0000] {standard_task_runner.py:57} INFO - Started process 498 to run task
[2025-05-07T01:22:55.886+0000] {standard_task_runner.py:84} INFO - Running: ['***', 'tasks', 'run', 'lgbtq_model_pipeline', 'retrain', 'scheduled__2025-05-06T00:00:00+00:00', '--job-id', '7', '--raw', '--subdir', 'DAGS_FOLDER/lgbtq_model_pipeline.py', '--cfg-path', '/tmp/tmpg3f3x4g8']
[2025-05-07T01:22:55.888+0000] {standard_task_runner.py:85} INFO - Job 7: Subtask retrain
[2025-05-07T01:22:55.912+0000] {task_command.py:416} INFO - Running <TaskInstance: lgbtq_model_pipeline.retrain scheduled__2025-05-06T00:00:00+00:00 [running]> on host ba7fb2e9095e
[2025-05-07T01:22:55.946+0000] {taskinstance.py:1662} INFO - Exporting env vars: AIRFLOW_CTX_DAG_OWNER='***' AIRFLOW_CTX_DAG_ID='lgbtq_model_pipeline' AIRFLOW_CTX_TASK_ID='retrain' AIRFLOW_CTX_EXECUTION_DATE='2025-05-06T00:00:00+00:00' AIRFLOW_CTX_TRY_NUMBER='1' AIRFLOW_CTX_DAG_RUN_ID='scheduled__2025-05-06T00:00:00+00:00'
[2025-05-07T01:22:55.947+0000] {logging_mixin.py:154} INFO - üì¶ Combining data...
[2025-05-07T01:22:56.089+0000] {logging_mixin.py:154} INFO - ‚ö†Ô∏è Skipping duplicate article_246
[2025-05-07T01:22:56.090+0000] {logging_mixin.py:154} INFO - ‚ö†Ô∏è Skipping duplicate article_247
[2025-05-07T01:22:56.091+0000] {logging_mixin.py:154} INFO - ‚ö†Ô∏è Skipping duplicate article_245
[2025-05-07T01:22:56.091+0000] {logging_mixin.py:154} INFO - ‚ö†Ô∏è Skipping duplicate article_248
[2025-05-07T01:22:56.092+0000] {logging_mixin.py:154} INFO - ‚ö†Ô∏è Skipping duplicate article_244
[2025-05-07T01:22:56.092+0000] {logging_mixin.py:154} INFO - üìö Loading labeled data...
[2025-05-07T01:22:56.184+0000] {logging_mixin.py:154} INFO - üß† Preparing triplet training data...
[2025-05-07T01:22:56.475+0000] {taskinstance.py:1937} ERROR - Task failed with exception
Traceback (most recent call last):
  File "/home/airflow/.local/lib/python3.8/site-packages/huggingface_hub/utils/_http.py", line 409, in hf_raise_for_status
    response.raise_for_status()
  File "/home/airflow/.local/lib/python3.8/site-packages/requests/models.py", line 1021, in raise_for_status
    raise HTTPError(http_error_msg, response=self)
requests.exceptions.HTTPError: 401 Client Error: Unauthorized for url: https://huggingface.co/all-MiniLM-L6-v2/resolve/main/tokenizer_config.json

The above exception was the direct cause of the following exception:

Traceback (most recent call last):
  File "/home/airflow/.local/lib/python3.8/site-packages/transformers/utils/hub.py", line 403, in cached_file
    resolved_file = hf_hub_download(
  File "/home/airflow/.local/lib/python3.8/site-packages/huggingface_hub/utils/_validators.py", line 114, in _inner_fn
    return fn(*args, **kwargs)
  File "/home/airflow/.local/lib/python3.8/site-packages/huggingface_hub/file_download.py", line 961, in hf_hub_download
    return _hf_hub_download_to_cache_dir(
  File "/home/airflow/.local/lib/python3.8/site-packages/huggingface_hub/file_download.py", line 1068, in _hf_hub_download_to_cache_dir
    _raise_on_head_call_error(head_call_error, force_download, local_files_only)
  File "/home/airflow/.local/lib/python3.8/site-packages/huggingface_hub/file_download.py", line 1596, in _raise_on_head_call_error
    raise head_call_error
  File "/home/airflow/.local/lib/python3.8/site-packages/huggingface_hub/file_download.py", line 1484, in _get_metadata_or_catch_error
    metadata = get_hf_file_metadata(
  File "/home/airflow/.local/lib/python3.8/site-packages/huggingface_hub/utils/_validators.py", line 114, in _inner_fn
    return fn(*args, **kwargs)
  File "/home/airflow/.local/lib/python3.8/site-packages/huggingface_hub/file_download.py", line 1401, in get_hf_file_metadata
    r = _request_wrapper(
  File "/home/airflow/.local/lib/python3.8/site-packages/huggingface_hub/file_download.py", line 285, in _request_wrapper
    response = _request_wrapper(
  File "/home/airflow/.local/lib/python3.8/site-packages/huggingface_hub/file_download.py", line 309, in _request_wrapper
    hf_raise_for_status(response)
  File "/home/airflow/.local/lib/python3.8/site-packages/huggingface_hub/utils/_http.py", line 459, in hf_raise_for_status
    raise _format(RepositoryNotFoundError, message, response) from e
huggingface_hub.errors.RepositoryNotFoundError: 401 Client Error. (Request ID: Root=1-681ab5f0-369442ed568036075e5aa781;febb7073-f76a-4b4b-9871-80387252a355)

Repository Not Found for url: https://huggingface.co/all-MiniLM-L6-v2/resolve/main/tokenizer_config.json.
Please make sure you specified the correct `repo_id` and `repo_type`.
If you are trying to access a private or gated repo, make sure you are authenticated. For more details, see https://huggingface.co/docs/huggingface_hub/authentication
Invalid username or password.

The above exception was the direct cause of the following exception:

Traceback (most recent call last):
  File "/home/airflow/.local/lib/python3.8/site-packages/airflow/operators/python.py", line 192, in execute
    return_value = self.execute_callable()
  File "/home/airflow/.local/lib/python3.8/site-packages/airflow/operators/python.py", line 209, in execute_callable
    return self.python_callable(*self.op_args, **self.op_kwargs)
  File "/opt/airflow/dags/tasks/retrain.py", line 65, in train_triplet_model
    triplet_dataset = get_triplet_dataset(texts, labels)
  File "/opt/airflow/dags/model_code/model.py", line 106, in get_triplet_dataset
    tokenizer = AutoTokenizer.from_pretrained(model_name)
  File "/home/airflow/.local/lib/python3.8/site-packages/transformers/models/auto/tokenization_auto.py", line 857, in from_pretrained
    tokenizer_config = get_tokenizer_config(pretrained_model_name_or_path, **kwargs)
  File "/home/airflow/.local/lib/python3.8/site-packages/transformers/models/auto/tokenization_auto.py", line 689, in get_tokenizer_config
    resolved_config_file = cached_file(
  File "/home/airflow/.local/lib/python3.8/site-packages/transformers/utils/hub.py", line 426, in cached_file
    raise EnvironmentError(
OSError: all-MiniLM-L6-v2 is not a local folder and is not a valid model identifier listed on 'https://huggingface.co/models'
If this is a private repository, make sure to pass a token having permission to this repo either by logging in with `huggingface-cli login` or by passing `token=<your_token>`
[2025-05-07T01:22:56.484+0000] {taskinstance.py:1400} INFO - Marking task as FAILED. dag_id=lgbtq_model_pipeline, task_id=retrain, execution_date=20250506T000000, start_date=20250507T012255, end_date=20250507T012256
[2025-05-07T01:22:56.492+0000] {standard_task_runner.py:104} ERROR - Failed to execute job 7 for task retrain (all-MiniLM-L6-v2 is not a local folder and is not a valid model identifier listed on 'https://huggingface.co/models'
If this is a private repository, make sure to pass a token having permission to this repo either by logging in with `huggingface-cli login` or by passing `token=<your_token>`; 498)
[2025-05-07T01:22:56.522+0000] {local_task_job_runner.py:228} INFO - Task exited with return code 1
[2025-05-07T01:22:56.539+0000] {taskinstance.py:2778} INFO - 0 downstream tasks scheduled from follow-on schedule check
