[2025-05-01T08:11:19.912+0000] {taskinstance.py:1159} INFO - Dependencies all met for dep_context=non-requeueable deps ti=<TaskInstance: lgbtq_model_pipeline.fetch_articles manual__2025-05-01T08:11:16.419838+00:00 [queued]>
[2025-05-01T08:11:19.917+0000] {taskinstance.py:1159} INFO - Dependencies all met for dep_context=requeueable deps ti=<TaskInstance: lgbtq_model_pipeline.fetch_articles manual__2025-05-01T08:11:16.419838+00:00 [queued]>
[2025-05-01T08:11:19.917+0000] {taskinstance.py:1361} INFO - Starting attempt 1 of 1
[2025-05-01T08:11:19.924+0000] {taskinstance.py:1382} INFO - Executing <Task(PythonOperator): fetch_articles> on 2025-05-01 08:11:16.419838+00:00
[2025-05-01T08:11:19.932+0000] {standard_task_runner.py:57} INFO - Started process 189 to run task
[2025-05-01T08:11:19.937+0000] {standard_task_runner.py:84} INFO - Running: ['***', 'tasks', 'run', 'lgbtq_model_pipeline', 'fetch_articles', 'manual__2025-05-01T08:11:16.419838+00:00', '--job-id', '136', '--raw', '--subdir', 'DAGS_FOLDER/lgbtq_model_pipeline.py', '--cfg-path', '/tmp/tmpzgm34dx0']
[2025-05-01T08:11:19.942+0000] {standard_task_runner.py:85} INFO - Job 136: Subtask fetch_articles
[2025-05-01T08:11:19.968+0000] {task_command.py:416} INFO - Running <TaskInstance: lgbtq_model_pipeline.fetch_articles manual__2025-05-01T08:11:16.419838+00:00 [running]> on host 94390661d686
[2025-05-01T08:11:20.021+0000] {taskinstance.py:1662} INFO - Exporting env vars: AIRFLOW_CTX_DAG_OWNER='***' AIRFLOW_CTX_DAG_ID='lgbtq_model_pipeline' AIRFLOW_CTX_TASK_ID='fetch_articles' AIRFLOW_CTX_EXECUTION_DATE='2025-05-01T08:11:16.419838+00:00' AIRFLOW_CTX_TRY_NUMBER='1' AIRFLOW_CTX_DAG_RUN_ID='manual__2025-05-01T08:11:16.419838+00:00'
[2025-05-01T08:11:20.023+0000] {logging_mixin.py:154} INFO - Fetching CSV data from Google Sheets...
[2025-05-01T08:11:22.112+0000] {taskinstance.py:1937} ERROR - Task failed with exception
Traceback (most recent call last):
  File "/home/airflow/.local/lib/python3.8/site-packages/pandas/core/indexes/base.py", line 3653, in get_loc
    return self._engine.get_loc(casted_key)
  File "pandas/_libs/index.pyx", line 147, in pandas._libs.index.IndexEngine.get_loc
  File "pandas/_libs/index.pyx", line 176, in pandas._libs.index.IndexEngine.get_loc
  File "pandas/_libs/hashtable_class_helper.pxi", line 7080, in pandas._libs.hashtable.PyObjectHashTable.get_item
  File "pandas/_libs/hashtable_class_helper.pxi", line 7088, in pandas._libs.hashtable.PyObjectHashTable.get_item
KeyError: 'text'

The above exception was the direct cause of the following exception:

Traceback (most recent call last):
  File "/home/airflow/.local/lib/python3.8/site-packages/airflow/operators/python.py", line 192, in execute
    return_value = self.execute_callable()
  File "/home/airflow/.local/lib/python3.8/site-packages/airflow/operators/python.py", line 209, in execute_callable
    return self.python_callable(*self.op_args, **self.op_kwargs)
  File "/opt/airflow/dags/tasks/fetch_articles.py", line 23, in run
    sample["full_text"] = sample["title"].fillna("") + " " + sample["text"].fillna("")
  File "/home/airflow/.local/lib/python3.8/site-packages/pandas/core/frame.py", line 3761, in __getitem__
    indexer = self.columns.get_loc(key)
  File "/home/airflow/.local/lib/python3.8/site-packages/pandas/core/indexes/base.py", line 3655, in get_loc
    raise KeyError(key) from err
KeyError: 'text'
[2025-05-01T08:11:22.136+0000] {taskinstance.py:1400} INFO - Marking task as FAILED. dag_id=lgbtq_model_pipeline, task_id=fetch_articles, execution_date=20250501T081116, start_date=20250501T081119, end_date=20250501T081122
[2025-05-01T08:11:22.149+0000] {standard_task_runner.py:104} ERROR - Failed to execute job 136 for task fetch_articles ('text'; 189)
[2025-05-01T08:11:22.165+0000] {local_task_job_runner.py:228} INFO - Task exited with return code 1
[2025-05-01T08:11:22.199+0000] {taskinstance.py:2778} INFO - 0 downstream tasks scheduled from follow-on schedule check
