[2025-05-08T09:22:36.470+0000] {taskinstance.py:1159} INFO - Dependencies all met for dep_context=non-requeueable deps ti=<TaskInstance: lgbtq_model_pipeline.human_review manual__2025-05-08T09:22:30.973377+00:00 [queued]>
[2025-05-08T09:22:36.474+0000] {taskinstance.py:1159} INFO - Dependencies all met for dep_context=requeueable deps ti=<TaskInstance: lgbtq_model_pipeline.human_review manual__2025-05-08T09:22:30.973377+00:00 [queued]>
[2025-05-08T09:22:36.474+0000] {taskinstance.py:1361} INFO - Starting attempt 1 of 1
[2025-05-08T09:22:36.481+0000] {taskinstance.py:1382} INFO - Executing <Task(PythonOperator): human_review> on 2025-05-08 09:22:30.973377+00:00
[2025-05-08T09:22:36.486+0000] {standard_task_runner.py:57} INFO - Started process 406 to run task
[2025-05-08T09:22:36.492+0000] {standard_task_runner.py:84} INFO - Running: ['***', 'tasks', 'run', 'lgbtq_model_pipeline', 'human_review', 'manual__2025-05-08T09:22:30.973377+00:00', '--job-id', '270', '--raw', '--subdir', 'DAGS_FOLDER/lgbtq_model_pipeline.py', '--cfg-path', '/tmp/tmpfhgtvlna']
[2025-05-08T09:22:36.494+0000] {standard_task_runner.py:85} INFO - Job 270: Subtask human_review
[2025-05-08T09:22:36.520+0000] {task_command.py:416} INFO - Running <TaskInstance: lgbtq_model_pipeline.human_review manual__2025-05-08T09:22:30.973377+00:00 [running]> on host 2f9495a2914d
[2025-05-08T09:22:36.564+0000] {taskinstance.py:1662} INFO - Exporting env vars: AIRFLOW_CTX_DAG_OWNER='***' AIRFLOW_CTX_DAG_ID='lgbtq_model_pipeline' AIRFLOW_CTX_TASK_ID='human_review' AIRFLOW_CTX_EXECUTION_DATE='2025-05-08T09:22:30.973377+00:00' AIRFLOW_CTX_TRY_NUMBER='1' AIRFLOW_CTX_DAG_RUN_ID='manual__2025-05-08T09:22:30.973377+00:00'
[2025-05-08T09:22:36.564+0000] {logging_mixin.py:154} INFO - ðŸ‘€ Checking for enough articles in review queue...
[2025-05-08T09:22:36.567+0000] {logging_mixin.py:154} WARNING - /home/***/.local/lib/python3.8/site-packages/pymongo/synchronous/mongo_client.py:2554 UserWarning: MongoClient opened before fork. May not be entirely fork-safe, proceed with caution. See PyMongo's documentation for details: https://www.mongodb.com/docs/languages/python/pymongo-driver/current/faq/#is-pymongo-fork-safe-
[2025-05-08T09:23:06.788+0000] {taskinstance.py:1937} ERROR - Task failed with exception
Traceback (most recent call last):
  File "/home/airflow/.local/lib/python3.8/site-packages/airflow/operators/python.py", line 192, in execute
    return_value = self.execute_callable()
  File "/home/airflow/.local/lib/python3.8/site-packages/airflow/operators/python.py", line 209, in execute_callable
    return self.python_callable(*self.op_args, **self.op_kwargs)
  File "/opt/airflow/dags/tasks/human_review.py", line 29, in run
    total_in_queue = review_queue.count_documents({})
  File "/home/airflow/.local/lib/python3.8/site-packages/pymongo/synchronous/collection.py", line 2134, in count_documents
    return self._retryable_non_cursor_read(_cmd, session, _Op.COUNT)
  File "/home/airflow/.local/lib/python3.8/site-packages/pymongo/synchronous/collection.py", line 2148, in _retryable_non_cursor_read
    return client._retryable_read(func, self._read_preference_for(s), s, operation)
  File "/home/airflow/.local/lib/python3.8/site-packages/pymongo/synchronous/mongo_client.py", line 1863, in _retryable_read
    return self._retry_internal(
  File "/home/airflow/.local/lib/python3.8/site-packages/pymongo/_csot.py", line 119, in csot_wrapper
    return func(self, *args, **kwargs)
  File "/home/airflow/.local/lib/python3.8/site-packages/pymongo/synchronous/mongo_client.py", line 1819, in _retry_internal
    return _ClientConnectionRetryable(
  File "/home/airflow/.local/lib/python3.8/site-packages/pymongo/synchronous/mongo_client.py", line 2554, in run
    return self._read() if self._is_read else self._write()
  File "/home/airflow/.local/lib/python3.8/site-packages/pymongo/synchronous/mongo_client.py", line 2689, in _read
    self._server = self._get_server()
  File "/home/airflow/.local/lib/python3.8/site-packages/pymongo/synchronous/mongo_client.py", line 2645, in _get_server
    return self._client._select_server(
  File "/home/airflow/.local/lib/python3.8/site-packages/pymongo/synchronous/mongo_client.py", line 1649, in _select_server
    server = topology.select_server(
  File "/home/airflow/.local/lib/python3.8/site-packages/pymongo/synchronous/topology.py", line 398, in select_server
    server = self._select_server(
  File "/home/airflow/.local/lib/python3.8/site-packages/pymongo/synchronous/topology.py", line 376, in _select_server
    servers = self.select_servers(
  File "/home/airflow/.local/lib/python3.8/site-packages/pymongo/synchronous/topology.py", line 283, in select_servers
    server_descriptions = self._select_servers_loop(
  File "/home/airflow/.local/lib/python3.8/site-packages/pymongo/synchronous/topology.py", line 333, in _select_servers_loop
    raise ServerSelectionTimeoutError(
pymongo.errors.ServerSelectionTimeoutError: localhost:27017: [Errno 111] Connection refused (configured timeouts: socketTimeoutMS: 20000.0ms, connectTimeoutMS: 20000.0ms), Timeout: 30s, Topology Description: <TopologyDescription id: 681c77dbd50d63361ca2549c, topology_type: Unknown, servers: [<ServerDescription ('localhost', 27017) server_type: Unknown, rtt: None, error=AutoReconnect('localhost:27017: [Errno 111] Connection refused (configured timeouts: socketTimeoutMS: 20000.0ms, connectTimeoutMS: 20000.0ms)')>]>
[2025-05-08T09:23:06.829+0000] {taskinstance.py:1400} INFO - Marking task as FAILED. dag_id=lgbtq_model_pipeline, task_id=human_review, execution_date=20250508T092230, start_date=20250508T092236, end_date=20250508T092306
[2025-05-08T09:23:06.851+0000] {standard_task_runner.py:104} ERROR - Failed to execute job 270 for task human_review (localhost:27017: [Errno 111] Connection refused (configured timeouts: socketTimeoutMS: 20000.0ms, connectTimeoutMS: 20000.0ms), Timeout: 30s, Topology Description: <TopologyDescription id: 681c77dbd50d63361ca2549c, topology_type: Unknown, servers: [<ServerDescription ('localhost', 27017) server_type: Unknown, rtt: None, error=AutoReconnect('localhost:27017: [Errno 111] Connection refused (configured timeouts: socketTimeoutMS: 20000.0ms, connectTimeoutMS: 20000.0ms)')>]>; 406)
[2025-05-08T09:23:06.871+0000] {local_task_job_runner.py:228} INFO - Task exited with return code 1
[2025-05-08T09:23:06.916+0000] {taskinstance.py:2778} INFO - 0 downstream tasks scheduled from follow-on schedule check
